Workbook
Name Karbohidrat_Nasi: 'DATA BANTU'!$A:$A
Name Lauk_Hewani_Telur_Ayam: 'DATA BANTU'!$G:$G
Name Sayur: 'DATA BANTU'!$S:$S
Name Lauk_Nabati_Tempe: 'DATA BANTU'!$O:$O
Name Lauk_Hewani_Ikan: 'DATA BANTU'!$K:$K
Name Lauk_Hewani_Ayam_Potong: 'DATA BANTU'!$C:$C
Name Lauk_Nabati_Lainnya: 'DATA BANTU'!$Q:$Q
Name Lauk_Nabati_Tahu: 'DATA BANTU'!$M:$M
Name Lauk_Hewani_Daging_Sapi: 'DATA BANTU'!$I:$I
Name Lauk_Hewani_Ayam_Fillet: 'DATA BANTU'!$E:$E
Name Buah: 'DATA BANTU'!$U:$U

Sheet KODE+STANDAR PORSI
A1: KODE MENU | D1: STANDAR PORSI
A2: KODE | B2: JENIS MENU | C2: NAMA MENU | D2: RINCIAN BAHAN UTAMA | E2: PORSI KECIL | F2: PORSI BESAR
A3: 1111 | B3: Karbohidrat (Nasi) | C3: Nasi Putih (Beras Premium) | D3: Nasi Premium | E3: 100 | F3: 180
A4: 1112 | B4: Karbohidrat (Nasi) | C4: Nasi Putih (Beras) | D4: Nasi | E4: 100 | F4: 180
A5: 1113 | B5: Karbohidrat (Nasi) | C5: Nasi Daun Jeruk (Beras Premium) | D5: Nasi Premium | E5: 100 | F5: 180
A6: 1114 | B6: Karbohidrat (Nasi) | C6: Nasi Daun Jeruk (Beras) | D6: Nasi | E6: 100 | F6: 180
A7: 1115 | B7: Karbohidrat (Nasi) | C7: Nasi Liwet (Beras Premium) | D7: Nasi Premium | E7: 100 | F7: 180
A8: 1116 | B8: Karbohidrat (Nasi) | C8: Nasi Liwet (Beras) | D8: Nasi | E8: 100 | F8: 180
A9: 1117 | B9: Karbohidrat (Nasi) | C9: Nasi Kuning (Beras Premium) | D9: Nasi Premium | E9: 100 | F9: 180
A10: 1118 | B10: Karbohidrat (Nasi) | C10: Nasi Kuning (Beras) | D10: Nasi | E10: 100 | F10: 180
A11: 1119 | B11: Karbohidrat (Nasi) | C11: Nasi Uduk (Beras Premium) | D11: Nasi Premium | E11: 100 | F11: 180
A12: 1120 | B12: Karbohidrat (Nasi) | C12: Nasi Uduk (Beras) | D12: Nasi | E12: 100 | F12: 180
A13: 2111 | B13: Lauk Hewani (Ayam Potong) | C13: Ayam Kremes | D13: Ayam Potong | E13: 48.3 | F13: 58
A14: 2112 | B14: Lauk Hewani (Ayam Potong) | C14: Ayam Kecap | D14: Ayam Potong | E14: 48.3 | F14: 58
... A72: 4124 | B72: Sayur | C72: Acar Bening Mentimun Wortel | D72: Wortel | E72: 20 | F72: 20
A73: 5111 | B73: Buah | C73: Pisang Ambon
A74: 5112 | B74: Buah | C74: Jeruk Medan Polos
A75: 5113 | B75: Buah | C75: Jeruk Medan Brastagi
A76: 5114 | B76: Buah | C76: Jeruk Pontianak
A77: 5115 | B77: Buah | C77: Kurma Sukari
A78: 5116 | B78: Buah | C78: Anggur Merah Australia
A79: 5117 | B79: Buah | C79: Kelengkeng Stiker Merah
A80: 5118 | B80: Buah | C80: Kelengkeng Stiker Biru
A81: 5119 | B81: Buah | C81: Apel Fuji (Uk 125)
A82: 5120 | B82: Buah | C82: Apel Fuji (Uk 138)
A83: 5121 | B83: Buah | C83: Pear Century
A84: 5122 | B84: Buah | C84: Jeruk Sunkist Neval

Sheet STANDAR RESEP
A1: STANDAR RESEP
A2: JENIS MENU | B2: NAMA MENU | C2: BAHAN | D2: KEBUTUHAN | E2: SATUAN | F2: RESEP PER
A3: Karbohidrat (Nasi) | B3: Nasi Daun Jeruk (Beras Premium) | C3: Nasi Premium | D3: 50000 | E3: g
A4: Karbohidrat (Nasi) | B4: Nasi Daun Jeruk (Beras Premium) | C4: Bawang Putih Kupas | D4: 1000 | E4: g
A5: Karbohidrat (Nasi) | B5: Nasi Daun Jeruk (Beras Premium) | C5: Sereh | D5: 1 | E5: ikat
A6: Karbohidrat (Nasi) | B6: Nasi Daun Jeruk (Beras Premium) | C6: Daun Jeruk | D6: 500 | E6: g
A7: Karbohidrat (Nasi) | B7: Nasi Daun Jeruk (Beras Premium) | C7: Garam Refina @500g
A8: Karbohidrat (Nasi) | B8: Nasi Daun Jeruk (Beras Premium) | C8: Totole Kaldu Jamur Non Kolesterol @1kg
A9: Karbohidrat (Nasi) | B9: Nasi Daun Jeruk (Beras) | C9: Nasi | D9: 50000 | E9: g
A10: Karbohidrat (Nasi) | B10: Nasi Daun Jeruk (Beras) | C10: Bawang Putih Kupas | D10: 1000 | E10: g
A11: Karbohidrat (Nasi) | B11: Nasi Daun Jeruk (Beras) | C11: Sereh | D11: 1 | E11: ikat
A12: Karbohidrat (Nasi) | B12: Nasi Daun Jeruk (Beras) | C12: Daun Jeruk | D12: 500 | E12: g
A13: Karbohidrat (Nasi) | B13: Nasi Daun Jeruk (Beras) | C13: Garam Refina @500g
A14: Karbohidrat (Nasi) | B14: Nasi Daun Jeruk (Beras) | C14: Totole Kaldu Jamur Non Kolesterol @1kg
A15: Karbohidrat (Nasi) | B15: Nasi Kuning (Beras Premium) | C15: Nasi Premium | D15: 50000 | E15: g
A16: Karbohidrat (Nasi) | B16: Nasi Kuning (Beras Premium) | C16: Santan Kelapa Sun Kara @1liter | D16: 6000 | E16: ml
A17: Karbohidrat (Nasi) | B17: Nasi Kuning (Beras Premium) | C17: Bumbu Dasar Kuning | D17: 2000 | E17: g
A18: Karbohidrat (Nasi) | B18: Nasi Kuning (Beras Premium) | C18: Kunyit Giling | D18: 250 | E18: g
A19: Karbohidrat (Nasi) | B19: Nasi Kuning (Beras Premium) | C19: Ketumbar Bubuk | D19: 150 | E19: g
A20: Karbohidrat (Nasi) | B20: Nasi Kuning (Beras Premium) | C20: Daun Salam | D20: 1 | E20: ikat
A21: Karbohidrat (Nasi) | B21: Nasi Kuning (Beras Premium) | C21: Sereh | D21: 1 | E21: ikat
A22: Karbohidrat (Nasi) | B22: Nasi Kuning (Beras Premium) | C22: Garam Refina @500g
A23: Karbohidrat (Nasi) | B23: Nasi Kuning (Beras Premium) | C23: Gula Pasir
A24: Karbohidrat (Nasi) | B24: Nasi Kuning (Beras Premium) | C24: Totole Kaldu Jamur Non Kolesterol @1kg
A25: Karbohidrat (Nasi) | B25: Nasi Kuning (Beras) | C25: Nasi | D25: 50000 | E25: g
A26: Karbohidrat (Nasi) | B26: Nasi Kuning (Beras) | C26: Santan Kelapa Sun Kara @1liter | D26: 6000 | E26: ml
A27: Karbohidrat (Nasi) | B27: Nasi Kuning (Beras) | C27: Bumbu Dasar Kuning | D27: 2000 | E27: g
A28: Karbohidrat (Nasi) | B28: Nasi Kuning (Beras) | C28: Kunyit Giling | D28: 250 | E28: g
A29: Karbohidrat (Nasi) | B29: Nasi Kuning (Beras) | C29: Ketumbar Bubuk | D29: 150 | E29: g
A30: Karbohidrat (Nasi) | B30: Nasi Kuning (Beras) | C30: Daun Salam | D30: 1 | E30: ikat
A31: Karbohidrat (Nasi) | B31: Nasi Kuning (Beras) | C31: Sereh | D31: 1 | E31: ikat
A32: Karbohidrat (Nasi) | B32: Nasi Kuning (Beras) | C32: Garam Refina @500g
A33: Karbohidrat (Nasi) | B33: Nasi Kuning (Beras) | C33: Gula Pasir
A34: Karbohidrat (Nasi) | B34: Nasi Kuning (Beras) | C34: Totole Kaldu Jamur Non Kolesterol @1kg
A35: Karbohidrat (Nasi) | B35: Nasi Liwet (Beras Premium) | C35: Nasi Premium | D35: 50000 | E35: g
A36: Karbohidrat (Nasi) | B36: Nasi Liwet (Beras Premium) | C36: Bawang Merah Iris | D36: 1000 | E36: g
A37: Karbohidrat (Nasi) | B37: Nasi Liwet (Beras Premium) | C37: Bawang Putih Kupas | D37: 1000 | E37: g
A38: Karbohidrat (Nasi) | B38: Nasi Liwet (Beras Premium) | C38: Daun Salam | D38: 1 | E38: ikat
A39: Karbohidrat (Nasi) | B39: Nasi Liwet (Beras Premium) | C39: Sereh | D39: 1 | E39: ikat
A40: Karbohidrat (Nasi) | B40: Nasi Liwet (Beras Premium) | C40: Garam Refina @500g
...

Sheet INFORMASI BAHAN PANGAN
D1: INFORMASI BAHAN PANGAN | J1: KATEGORI BAHAN PANGAN
A2: KOLOM BANTU 1 | B2: KOLOM BANTU 2 | C2: KOLOM BANTU 3 | D2: NAMA BAHAN | E2: %BDD | F2: HARGA | G2: SATUAN | H2: UNIT BELI | J2: Bahan Utama | K2: Bumbu Pelengkap | L2: Bumbu Dasar
A3: {=UNIQUE('KODE+STANDAR PORSI'!D3:D1014)} -> Nasi Premium | B3: {=SORT(UNIQUE('STANDAR RESEP'!C4:C1042))} -> Asam Jawa | C3: {=SORT(UNIQUE({TOCOL(A3:A1002, 1); TOCOL(B3:B1002, 1)}))} -> Asam Jawa | D3: Asam Jawa | E3: 1 | F3: 27000 | G3: kg | H3: 1000 | J3: Nasi | K3: Bihun Jagung Padamu @300g | L3: Asam Jawa
A4: Nasi | B4: Ayam Fillet | C4: Ayam Fillet | D4: Ayam Fillet | E4: 1 | F4: 56000 | G4: kg | H4: 1000 | J4: Nasi Premium | K4: Blue Band Margarin | L4: Baking Powder Koepoe-Koepoe @45g
A5: Ayam Potong | B5: Ayam Potong | C5: Ayam Potong | D5: Ayam Potong | E5: 0.58 | F5: 40000 | G5: kg | H5: 1000 | J5: Ayam Potong | K5: Garam Refina @500g | L5: Bawang Bombay
A6: Ayam Fillet | B6: Baking Powder Koepoe-Koepoe @45g | C6: Baking Powder Koepoe-Koepoe @45g | D6: Baking Powder Koepoe-Koepoe @45g | E6: 1 | F6: 8000 | G6: botol | H6: 45 | J6: Ayam Fillet | K6: Gula Aren | L6: Bawang Merah Iris
A7: Telur Ayam | B7: Bawang Bombay | C7: Bawang Bombay | D7: Bawang Bombay | E7: 1 | F7: 40000 | G7: kg | H7: 1000 | J7: Telur Ayam | K7: Gula Pasir | L7: Bawang Merah Kupas
A8: Daging Sapi | B8: Bawang Merah Iris | C8: Bawang Merah Iris | D8: Bawang Merah Iris | E8: 1 | F8: 55000 | G8: kg | H8: 1000 | J8: Daging Sapi | K8: Kecap Asin ABC @620ml | L8: Bawang Putih Giling
A9: Ikan Nila | B9: Bawang Merah Kupas | C9: Bawang Merah Kupas | D9: Bawang Merah Kupas | E9: 1 | G9: kg | H9: 1000 | J9: Ikan Nila | K9: Kecap Inggris ABC @195ml | L9: Bawang Putih Kupas
A10: Ikan Tuna | B10: Bawang Putih Giling | C10: Bawang Putih Giling | D10: Bawang Putih Giling | E10: 1 | G10: kg | H10: 1000 | J10: Ikan Tuna | K10: Kecap Manis ABC @825g | L10: Bumbu Dasar Acar Kuning
A11: Ikan Lele Fillet | B11: Bawang Putih Kupas | C11: Bawang Putih Kupas | D11: Bawang Putih Kupas | E11: 1 | F11: 45000 | G11: kg | H11: 1000 | J11: Ikan Lele | K11: Kelapa Parut | L11: Bumbu Dasar Balado
A12: Tahu | B12: Bihun Jagung Padamu @300g | C12: Bayam | D12: Bayam | E12: 0.8 | G12: kg | H12: 1000 | J12: Tahu | K12: Kol | L12: Bumbu Dasar Gulai Kuning
A13: Tempe | B13: Blue Band Margarin | C13: Bihun Jagung Padamu @300g | D13: Bihun Jagung Padamu @300g | E13: 1 | G13: pcs | H13: 300 | J13: Tempe | K13: Maizena | L13: Bumbu Dasar Kuning
A14: Edamame | B14: Bumbu Dasar Acar Kuning | C14: Blue Band Margarin | D14: Blue Band Margarin | E14: 1 | F14: 43000 | G14: kg | H14: 1000 | J14: Edamame | K14: Minyak Wijen @600ml | L14: Bumbu Dasar Kuning (Kunyit Sedikit)
A15: Susu UHT Ultra Full Cream 125 ml | B15: Bumbu Dasar Balado | C15: Bumbu Dasar Acar Kuning | D15: Bumbu Dasar Acar Kuning | E15: 1 | F15: 40000 | G15: kg | H15: 1000 | J15: Susu UHT Ultra Full Cream 125 ml | K15: Santan Kelapa Murni | L15: Bumbu Dasar Pesmol (Kunyit Sedikit)
A16: Susu UHT Cimory Full Cream 125 ml | B16: Bumbu Dasar Gulai Kuning | C16: Bumbu Dasar Balado | D16: Bumbu Dasar Balado | E16: 1 | F16: 40000 | G16: kg | H16: 1000 | J16: Susu UHT Cimory Full Cream 125 ml | K16: Santan Kelapa Sun Kara @1liter | L16: Bumbu Dasar Putih
A17: Labu Siam | B17: Bumbu Dasar Kari Ayam Kuning | C17: Bumbu Dasar Gulai Kuning | D17: Bumbu Dasar Gulai Kuning | E17: 1 | G17: kg | H17: 1000 | J17: Labu Siam | K17: Saus Barbeque Delmonte @1kg | L17: Bumbu Dasar Rendang
A18: Wortel | B18: Bumbu Dasar Kuning | C18: Bumbu Dasar Kari Ayam Kuning | D18: Bumbu Dasar Kari Ayam Kuning | E18: 1 | G18: kg | H18: 1000 | J18: Wortel | K18: Saus Bulgogi Saori @133ml | L18: Bumbu Dasar Rica
A19: Kangkung | B19: Bumbu Dasar Kuning (Kunyit Sedikit) | C19: Bumbu Dasar Kuning | D19: Bumbu Dasar Kuning | E19: 1 | F19: 40000 | G19: kg | H19: 1000 | J19: Kangkung | K19: Saus Sambal Delmonte Extra Hot @1kg | L19: Bumbu Dasar Kari Ayam Kuning
A20: Buncis | B20: Bumbu Dasar Pesmol (Kunyit Sedikit) | C20: Bumbu Dasar Kuning (Kunyit Sedikit) | D20: Bumbu Dasar Kuning (Kunyit Sedikit) | E20: 1 | F20: 40000 | G20: kg | H20: 1000 | J20: Buncis | K20: Saus Teriyaki Saori @1liter | L20: Bunga Lawang
A21: Selada | B21: Bumbu Dasar Putih | C21: Bumbu Dasar Pesmol (Kunyit Sedikit) | D21: Bumbu Dasar Pesmol (Kunyit Sedikit) | E21: 1 | F21: 40000 | G21: kg | H21: 1000 | J21: Selada | K21: Saus Tiram Saori @1liter | L21: Cabai Hijau Besar
A22: Mentimun | B22: Bumbu Dasar Rendang | C22: Bumbu Dasar Putih | D22: Bumbu Dasar Putih | E22: 1 | F22: 40000 | G22: kg | H22: 1000 | J22: Mentimun | K22: Saus Tomat Delmonte @1kg | L22: Cabai Merah Besar
A23: Sawi Putih | B23: Bumbu Dasar Rica | C23: Bumbu Dasar Rendang | D23: Bumbu Dasar Rendang | E23: 1 | G23: kg | H23: 1000 | J23: Sawi Putih | K23: Telur Ayam | L23: Cabai Merah Besar Giling
A24: Bayam | B24: Bunga Lawang | C24: Bumbu Dasar Rica | D24: Bumbu Dasar Rica | E24: 1 | F24: 40000 | G24: kg | H24: 1000 | J24: Bayam | K24: Tepung Beras Rose Brand @500g | L24: Cuka Makan Dixi @650ml
A25: Jagung Manis Kupas | B25: Cabai Hijau Besar | C25: Buncis | D25: Buncis | E25: 0.9 | F25: 14000 | G25: kg | H25: 1000 | J25: Jagung Manis Kupas | K25: Tepung Bumbu Kentucky Sasa @850g | L25: Daun Bawang
A26: Kacang Panjang | B26: Cabai Merah Besar | C26: Bunga Lawang | D26: Bunga Lawang | E26: 1 | G26: kg | H26: 1000 | J26: Kacang Panjang | K26: Tepung Bumbu Serbaguna Sasa @900g | L26: Daun Jeruk
A27: Daun Singkong | B27: Cabai Merah Besar Giling | C27: Cabai Hijau Besar | D27: Cabai Hijau Besar | E27: 1 | F27: 20000 | G27: kg | H27: 1000 | J27: Daun Singkong | K27: Tepung Terigu Cakra Kembar @1kg | L27: Daun Kari
A28: Nangka Muda | B28: Cuka Makan Dixi @650ml | C28: Cabai Merah Besar | D28: Cabai Merah Besar | E28: 1 | F28: 37000 | G28: kg | H28: 1000 | J28: Nangka Muda | K28: Tepung Terigu Lencana Merah @1kg | L28: Daun Kemangi
A29: Kol | B29: Daging Sapi | C29: Cabai Merah Besar Giling | D29: Cabai Merah Besar Giling | E29: 1 | F29: 60000 | G29: kg | H29: 1000 | J29: Kol | K29: Totole Kaldu Jamur Non Kolesterol @1kg | L29: Daun Kunyit
A30: Jagung Pipil | B30: Daun Bawang | C30: Caisim | D30: Caisim | E30: 0.87 | F30: 10000 | G30: kg | H30: 1000 | J30: Caisim | K30: Wortel | L30: Daun Salam
A31: Caisim | B31: Daun Jeruk | C31: Cuka Makan Dixi @650ml | D31: Cuka Makan Dixi @650ml | E31: 1 | F31: 18000 | G31: botol | H31: 650 | J31: Jamur Kuping | L31: Daun Seledri
A32: Jamur Kuping | B32: Daun Kari | C32: Daging Sapi | D32: Daging Sapi | E32: 1 | G32: kg | H32: 1000 | L32: Jahe Bonggol
A33: Mentimun (Acar) | B33: Daun Kemangi | C33: Daun Bawang | D33: Daun Bawang | E33: 1 | F33: 15000 | G33: kg | H33: 1000 | L33: Jahe Giling
B34: Daun Kunyit | C34: Daun Jeruk | D34: Daun Jeruk | E34: 1 | F34: 70000 | G34: kg | H34: 1000 | L34: Kapulaga
B35: Daun Salam | C35: Daun Kari | D35: Daun Kari | E35: 1 | G35: ikat | H35: 1 | L35: Kayu Manis
B36: Daun Seledri | C36: Daun Kemangi | D36: Daun Kemangi | E36: 1 | F36: 35000 | G36: kg | H36: 1000 | L36: Kencur
B37: Edamame | C37: Daun Kunyit | D37: Daun Kunyit | E37: 1 | F37: 6000 | G37: ikat | H37: 1 | L37: Ketumbar Bubuk
B38: Garam Refina @500g | C38: Daun Salam | D38: Daun Salam | E38: 1 | F38: 8500 | G38: ikat | H38: 1 | L38: Kunyit Giling
B39: Gula Aren | C39: Daun Seledri | D39: Daun Seledri | E39: 1 | G39: kg | H39: 1000 | L39: Lada Putih Bubuk
B40: Gula Pasir | C40: Daun Singkong | D40: Daun Singkong | E40: 0.87 | G40: kg | H40: 1000 | L40: Lengkuas Bonggol
...

Sheet DATA BANTU
A1: =IFERROR(__xludf.DUMMYFUNCTION("SORT(UNIQUE(FILTER('KODE+STANDAR PORSI'!C:C,'KODE+STANDAR PORSI'!B:B='KODE+STANDAR PORSI'!B3)))"),"Nasi Daun Jeruk (Beras Premium)") -> Nasi Daun Jeruk (Beras Premium) | C1: =IFERROR(__xludf.DUMMYFUNCTION("SORT(UNIQUE(FILTER('KODE+STANDAR PORSI'!C:C,'KODE+STANDAR PORSI'!B:B='KODE+STANDAR PORSI'!B13)))"),"Ayam Kecap") -> Ayam Kecap | E1: =IFERROR(__xludf.DUMMYFUNCTION("SORT(UNIQUE(FILTER('KODE+STANDAR PORSI'!C:C,'KODE+STANDAR PORSI'!B:B='KODE+STANDAR PORSI'!B19)))"),"Ayam Fillet Saus Barbeque") -> Ayam Fillet Saus Barbeque | G1: =IFERROR(__xludf.DUMMYFUNCTION("SORT(UNIQUE(FILTER('KODE+STANDAR PORSI'!C:C,'KODE+STANDAR PORSI'!B:B='KODE+STANDAR PORSI'!B25)))"),"Balado Telur") -> Balado Telur | I1: =IFERROR(__xludf.DUMMYFUNCTION("SORT(UNIQUE(FILTER('KODE+STANDAR PORSI'!C:C,'KODE+STANDAR PORSI'!B:B='KODE+STANDAR PORSI'!B30)))"),"Beef Slice Barbeque") -> Beef Slice Barbeque | K1: =IFERROR(__xludf.DUMMYFUNCTION("SORT(UNIQUE(FILTER('KODE+STANDAR PORSI'!C:C,'KODE+STANDAR PORSI'!B:B='KODE+STANDAR PORSI'!B34)))"),"Lele Fillet Crispy") -> Lele Fillet Crispy | M1: =IFERROR(__xludf.DUMMYFUNCTION("SORT(UNIQUE(FILTER('KODE+STANDAR PORSI'!C:C,'KODE+STANDAR PORSI'!B:B='KODE+STANDAR PORSI'!B38)))"),"Tahu Fantasy") -> Tahu Fantasy | O1: =IFERROR(__xludf.DUMMYFUNCTION("SORT(UNIQUE(FILTER('KODE+STANDAR PORSI'!C:C,'KODE+STANDAR PORSI'!B:B='KODE+STANDAR PORSI'!B41)))"),"Kering Tempe") -> Kering Tempe | Q1: =IFERROR(__xludf.DUMMYFUNCTION("SORT(UNIQUE(FILTER('KODE+STANDAR PORSI'!C:C,'KODE+STANDAR PORSI'!B:B='KODE+STANDAR PORSI'!B44)))"),"Edamame") -> Edamame | S1: =IFERROR(__xludf.DUMMYFUNCTION("SORT(UNIQUE(FILTER('KODE+STANDAR PORSI'!C:C,'KODE+STANDAR PORSI'!B:B='KODE+STANDAR PORSI'!B47)))"),"Acar Bening Mentimun Wortel") -> Acar Bening Mentimun Wortel | U1: =IFERROR(__xludf.DUMMYFUNCTION("SORT(UNIQUE(FILTER('KODE+STANDAR PORSI'!C:C,'KODE+STANDAR PORSI'!B:B='KODE+STANDAR PORSI'!B73)))"),"Anggur Merah Australia") -> Anggur Merah Australia
A2: =IFERROR(__xludf.DUMMYFUNCTION("""COMPUTED_VALUE"""),"Nasi Daun Jeruk (Beras)") -> Nasi Daun Jeruk (Beras) | C2: =IFERROR(__xludf.DUMMYFUNCTION("""COMPUTED_VALUE"""),"Ayam Kentucky") -> Ayam Kentucky | E2: =IFERROR(__xludf.DUMMYFUNCTION("""COMPUTED_VALUE"""),"Ayam Fillet Saus Mentega") -> Ayam Fillet Saus Mentega | G2: =IFERROR(__xludf.DUMMYFUNCTION("""COMPUTED_VALUE"""),"Semur Telur") -> Semur Telur | I2: =IFERROR(__xludf.DUMMYFUNCTION("""COMPUTED_VALUE"""),"Krecek Daging") -> Krecek Daging | K2: =IFERROR(__xludf.DUMMYFUNCTION("""COMPUTED_VALUE"""),"Pesmol Nila") -> Pesmol Nila | M2: =IFERROR(__xludf.DUMMYFUNCTION("""COMPUTED_VALUE"""),"Tahu Goreng") -> Tahu Goreng | O2: =IFERROR(__xludf.DUMMYFUNCTION("""COMPUTED_VALUE"""),"Tempe Goreng") -> Tempe Goreng | Q2: =IFERROR(__xludf.DUMMYFUNCTION("""COMPUTED_VALUE"""),"Susu UHT Cimory Full Cream 125 ml") -> Susu UHT Cimory Full Cream 125 ml | S2: =IFERROR(__xludf.DUMMYFUNCTION("""COMPUTED_VALUE"""),"Acar Kuning Buncis") -> Acar Kuning Buncis | U2: =IFERROR(__xludf.DUMMYFUNCTION("""COMPUTED_VALUE"""),"Apel Fuji (Uk 125)") -> Apel Fuji (Uk 125)
A3: =IFERROR(__xludf.DUMMYFUNCTION("""COMPUTED_VALUE"""),"Nasi Kuning (Beras Premium)") -> Nasi Kuning (Beras Premium) | C3: =IFERROR(__xludf.DUMMYFUNCTION("""COMPUTED_VALUE"""),"Ayam Kremes") -> Ayam Kremes | E3: =IFERROR(__xludf.DUMMYFUNCTION("""COMPUTED_VALUE"""),"Ayam Fillet Saus Teriyaki") -> Ayam Fillet Saus Teriyaki | G3: =IFERROR(__xludf.DUMMYFUNCTION("""COMPUTED_VALUE"""),"Telur Ceplok") -> Telur Ceplok | I3: =IFERROR(__xludf.DUMMYFUNCTION("""COMPUTED_VALUE"""),"Rendang Daging") -> Rendang Daging | K3: =IFERROR(__xludf.DUMMYFUNCTION("""COMPUTED_VALUE"""),"Tuna Suwir Bumbu Kuning") -> Tuna Suwir Bumbu Kuning | M3: =IFERROR(__xludf.DUMMYFUNCTION("""COMPUTED_VALUE"""),"Tahu Saus Asam Manis") -> Tahu Saus Asam Manis | O3: =IFERROR(__xludf.DUMMYFUNCTION("""COMPUTED_VALUE"""),"Tempe Goreng Tepung") -> Tempe Goreng Tepung | Q3: =IFERROR(__xludf.DUMMYFUNCTION("""COMPUTED_VALUE"""),"Susu UHT Ultra Full Cream 125 ml") -> Susu UHT Ultra Full Cream 125 ml | S3: =IFERROR(__xludf.DUMMYFUNCTION("""COMPUTED_VALUE"""),"Capcay") -> Capcay | U3: =IFERROR(__xludf.DUMMYFUNCTION("""COMPUTED_VALUE"""),"Apel Fuji (Uk 138)") -> Apel Fuji (Uk 138) | Y3: {=IF('STANDAR RESEP'!A3="", "", TRANSPOSE(INDIRECT(SUBSTITUTE(SUBSTITUTE(SUBSTITUTE('STANDAR RESEP'!A3, " ", "_"), "(", ""), ")", ""))))} -> Nasi Daun Jeruk (Beras Premium) | Z3: Nasi Daun Jeruk (Beras) | AA3: Nasi Kuning (Beras Premium) | AB3: Nasi Kuning (Beras) | AC3: Nasi Liwet (Beras Premium) | AD3: Nasi Liwet (Beras) | AE3: Nasi Putih (Beras Premium) | AF3: Nasi Putih (Beras) | AG3: Nasi Uduk (Beras Premium) | AH3: Nasi Uduk (Beras)
A4: =IFERROR(__xludf.DUMMYFUNCTION("""COMPUTED_VALUE"""),"Nasi Kuning (Beras)") -> Nasi Kuning (Beras) | C4: =IFERROR(__xludf.DUMMYFUNCTION("""COMPUTED_VALUE"""),"Ayam Serundeng") -> Ayam Serundeng | E4: =IFERROR(__xludf.DUMMYFUNCTION("""COMPUTED_VALUE"""),"Ayam Suwir Kecap") -> Ayam Suwir Kecap | G4: =IFERROR(__xludf.DUMMYFUNCTION("""COMPUTED_VALUE"""),"Telur Dadar") -> Telur Dadar | I4: =IFERROR(__xludf.DUMMYFUNCTION("""COMPUTED_VALUE"""),"Semur Daging") -> Semur Daging | K4: =IFERROR(__xludf.DUMMYFUNCTION("""COMPUTED_VALUE"""),"Tuna Suwir Bumbu Rica") -> Tuna Suwir Bumbu Rica | S4: =IFERROR(__xludf.DUMMYFUNCTION("""COMPUTED_VALUE"""),"Gulai Daun Singkong Nangka Muda") -> Gulai Daun Singkong Nangka Muda | U4: =IFERROR(__xludf.DUMMYFUNCTION("""COMPUTED_VALUE"""),"Jeruk Medan Brastagi") -> Jeruk Medan Brastagi | Y4: {=IF('STANDAR RESEP'!A4="", "", TRANSPOSE(INDIRECT(SUBSTITUTE(SUBSTITUTE(SUBSTITUTE('STANDAR RESEP'!A4, " ", "_"), "(", ""), ")", ""))))} -> Nasi Daun Jeruk (Beras Premium) | Z4: Nasi Daun Jeruk (Beras) | AA4: Nasi Kuning (Beras Premium) | AB4: Nasi Kuning (Beras) | AC4: Nasi Liwet (Beras Premium) | AD4: Nasi Liwet (Beras) | AE4: Nasi Putih (Beras Premium) | AF4: Nasi Putih (Beras) | AG4: Nasi Uduk (Beras Premium) | AH4: Nasi Uduk (Beras)
A5: =IFERROR(__xludf.DUMMYFUNCTION("""COMPUTED_VALUE"""),"Nasi Liwet (Beras Premium)") -> Nasi Liwet (Beras Premium) | C5: =IFERROR(__xludf.DUMMYFUNCTION("""COMPUTED_VALUE"""),"Ayam Woku Kuning") -> Ayam Woku Kuning | E5: =IFERROR(__xludf.DUMMYFUNCTION("""COMPUTED_VALUE"""),"Ayam Suwir Kemangi Bumbu Kuning") -> Ayam Suwir Kemangi Bumbu Kuning | G5: =IFERROR(__xludf.DUMMYFUNCTION("""COMPUTED_VALUE"""),"Telur Dadar Padang") -> Telur Dadar Padang | S5: =IFERROR(__xludf.DUMMYFUNCTION("""COMPUTED_VALUE"""),"Lalap Mentimun") -> Lalap Mentimun | U5: =IFERROR(__xludf.DUMMYFUNCTION("""COMPUTED_VALUE"""),"Jeruk Medan Polos") -> Jeruk Medan Polos | Y5: {=IF('STANDAR RESEP'!A5="", "", TRANSPOSE(INDIRECT(SUBSTITUTE(SUBSTITUTE(SUBSTITUTE('STANDAR RESEP'!A5, " ", "_"), "(", ""), ")", ""))))} -> Nasi Daun Jeruk (Beras Premium) | Z5: Nasi Daun Jeruk (Beras) | AA5: Nasi Kuning (Beras Premium) | AB5: Nasi Kuning (Beras) | AC5: Nasi Liwet (Beras Premium) | AD5: Nasi Liwet (Beras) | AE5: Nasi Putih (Beras Premium) | AF5: Nasi Putih (Beras) | AG5: Nasi Uduk (Beras Premium) | AH5: Nasi Uduk (Beras)
A6: =IFERROR(__xludf.DUMMYFUNCTION("""COMPUTED_VALUE"""),"Nasi Liwet (Beras)") -> Nasi Liwet (Beras) | C6: =IFERROR(__xludf.DUMMYFUNCTION("""COMPUTED_VALUE"""),"Kari Ayam Kental") -> Kari Ayam Kental | E6: =IFERROR(__xludf.DUMMYFUNCTION("""COMPUTED_VALUE"""),"Ayam Suwir Kemangi Bumbu Rica") -> Ayam Suwir Kemangi Bumbu Rica | S6: =IFERROR(__xludf.DUMMYFUNCTION("""COMPUTED_VALUE"""),"Lalap Selada Mentimun") -> Lalap Selada Mentimun | U6: =IFERROR(__xludf.DUMMYFUNCTION("""COMPUTED_VALUE"""),"Jeruk Pontianak") -> Jeruk Pontianak | Y6: {=IF('STANDAR RESEP'!A6="", "", TRANSPOSE(INDIRECT(SUBSTITUTE(SUBSTITUTE(SUBSTITUTE('STANDAR RESEP'!A6, " ", "_"), "(", ""), ")", ""))))} -> Nasi Daun Jeruk (Beras Premium) | Z6: Nasi Daun Jeruk (Beras) | AA6: Nasi Kuning (Beras Premium) | AB6: Nasi Kuning (Beras) | AC6: Nasi Liwet (Beras Premium) | AD6: Nasi Liwet (Beras) | AE6: Nasi Putih (Beras Premium) | AF6: Nasi Putih (Beras) | AG6: Nasi Uduk (Beras Premium) | AH6: Nasi Uduk (Beras)
A7: =IFERROR(__xludf.DUMMYFUNCTION("""COMPUTED_VALUE"""),"Nasi Putih (Beras Premium)") -> Nasi Putih (Beras Premium) | S7: =IFERROR(__xludf.DUMMYFUNCTION("""COMPUTED_VALUE"""),"Tumis Bayam Jagung Pipil") -> Tumis Bayam Jagung Pipil | U7: =IFERROR(__xludf.DUMMYFUNCTION("""COMPUTED_VALUE"""),"Jeruk Sunkist Neval") -> Jeruk Sunkist Neval | Y7: {=IF('STANDAR RESEP'!A7="", "", TRANSPOSE(INDIRECT(SUBSTITUTE(SUBSTITUTE(SUBSTITUTE('STANDAR RESEP'!A7, " ", "_"), "(", ""), ")", ""))))} -> Nasi Daun Jeruk (Beras Premium) | Z7: Nasi Daun Jeruk (Beras) | AA7: Nasi Kuning (Beras Premium) | AB7: Nasi Kuning (Beras) | AC7: Nasi Liwet (Beras Premium) | AD7: Nasi Liwet (Beras) | AE7: Nasi Putih (Beras Premium) | AF7: Nasi Putih (Beras) | AG7: Nasi Uduk (Beras Premium) | AH7: Nasi Uduk (Beras)
A8: =IFERROR(__xludf.DUMMYFUNCTION("""COMPUTED_VALUE"""),"Nasi Putih (Beras)") -> Nasi Putih (Beras) | S8: =IFERROR(__xludf.DUMMYFUNCTION("""COMPUTED_VALUE"""),"Tumis Buncis Wortel") -> Tumis Buncis Wortel | U8: =IFERROR(__xludf.DUMMYFUNCTION("""COMPUTED_VALUE"""),"Kelengkeng Stiker Biru") -> Kelengkeng Stiker Biru | Y8: {=IF('STANDAR RESEP'!A8="", "", TRANSPOSE(INDIRECT(SUBSTITUTE(SUBSTITUTE(SUBSTITUTE('STANDAR RESEP'!A8, " ", "_"), "(", ""), ")", ""))))} -> Nasi Daun Jeruk (Beras Premium) | Z8: Nasi Daun Jeruk (Beras) | AA8: Nasi Kuning (Beras Premium) | AB8: Nasi Kuning (Beras) | AC8: Nasi Liwet (Beras Premium) | AD8: Nasi Liwet (Beras) | AE8: Nasi Putih (Beras Premium) | AF8: Nasi Putih (Beras) | AG8: Nasi Uduk (Beras Premium) | AH8: Nasi Uduk (Beras)
A9: =IFERROR(__xludf.DUMMYFUNCTION("""COMPUTED_VALUE"""),"Nasi Uduk (Beras Premium)") -> Nasi Uduk (Beras Premium) | S9: =IFERROR(__xludf.DUMMYFUNCTION("""COMPUTED_VALUE"""),"Tumis Kacang Panjang") -> Tumis Kacang Panjang | U9: =IFERROR(__xludf.DUMMYFUNCTION("""COMPUTED_VALUE"""),"Kelengkeng Stiker Merah") -> Kelengkeng Stiker Merah | Y9: {=IF('STANDAR RESEP'!A9="", "", TRANSPOSE(INDIRECT(SUBSTITUTE(SUBSTITUTE(SUBSTITUTE('STANDAR RESEP'!A9, " ", "_"), "(", ""), ")", ""))))} -> Nasi Daun Jeruk (Beras Premium) | Z9: Nasi Daun Jeruk (Beras) | AA9: Nasi Kuning (Beras Premium) | AB9: Nasi Kuning (Beras) | AC9: Nasi Liwet (Beras Premium) | AD9: Nasi Liwet (Beras) | AE9: Nasi Putih (Beras Premium) | AF9: Nasi Putih (Beras) | AG9: Nasi Uduk (Beras Premium) | AH9: Nasi Uduk (Beras)
A10: =IFERROR(__xludf.DUMMYFUNCTION("""COMPUTED_VALUE"""),"Nasi Uduk (Beras)") -> Nasi Uduk (Beras) | S10: =IFERROR(__xludf.DUMMYFUNCTION("""COMPUTED_VALUE"""),"Tumis Kangkung") -> Tumis Kangkung | U10: =IFERROR(__xludf.DUMMYFUNCTION("""COMPUTED_VALUE"""),"Kurma Sukari") -> Kurma Sukari | Y10: {=IF('STANDAR RESEP'!A10="", "", TRANSPOSE(INDIRECT(SUBSTITUTE(SUBSTITUTE(SUBSTITUTE('STANDAR RESEP'!A10, " ", "_"), "(", ""), ")", ""))))} -> Nasi Daun Jeruk (Beras Premium) | Z10: Nasi Daun Jeruk (Beras) | AA10: Nasi Kuning (Beras Premium) | AB10: Nasi Kuning (Beras) | AC10: Nasi Liwet (Beras Premium) | AD10: Nasi Liwet (Beras) | AE10: Nasi Putih (Beras Premium) | AF10: Nasi Putih (Beras) | AG10: Nasi Uduk (Beras Premium) | AH10: Nasi Uduk (Beras)
S11: =IFERROR(__xludf.DUMMYFUNCTION("""COMPUTED_VALUE"""),"Tumis Kol Wortel") -> Tumis Kol Wortel | U11: =IFERROR(__xludf.DUMMYFUNCTION("""COMPUTED_VALUE"""),"Pear Century") -> Pear Century | Y11: {=IF('STANDAR RESEP'!A11="", "", TRANSPOSE(INDIRECT(SUBSTITUTE(SUBSTITUTE(SUBSTITUTE('STANDAR RESEP'!A11, " ", "_"), "(", ""), ")", ""))))} -> Nasi Daun Jeruk (Beras Premium) | Z11: Nasi Daun Jeruk (Beras) | AA11: Nasi Kuning (Beras Premium) | AB11: Nasi Kuning (Beras) | AC11: Nasi Liwet (Beras Premium) | AD11: Nasi Liwet (Beras) | AE11: Nasi Putih (Beras Premium) | AF11: Nasi Putih (Beras) | AG11: Nasi Uduk (Beras Premium) | AH11: Nasi Uduk (Beras)
S12: =IFERROR(__xludf.DUMMYFUNCTION("""COMPUTED_VALUE"""),"Tumis Labu Siam Wortel") -> Tumis Labu Siam Wortel | U12: =IFERROR(__xludf.DUMMYFUNCTION("""COMPUTED_VALUE"""),"Pisang Ambon") -> Pisang Ambon | Y12: {=IF('STANDAR RESEP'!A12="", "", TRANSPOSE(INDIRECT(SUBSTITUTE(SUBSTITUTE(SUBSTITUTE('STANDAR RESEP'!A12, " ", "_"), "(", ""), ")", ""))))} -> Nasi Daun Jeruk (Beras Premium) | Z12: Nasi Daun Jeruk (Beras) | AA12: Nasi Kuning (Beras Premium) | AB12: Nasi Kuning (Beras) | AC12: Nasi Liwet (Beras Premium) | AD12: Nasi Liwet (Beras) | AE12: Nasi Putih (Beras Premium) | AF12: Nasi Putih (Beras) | AG12: Nasi Uduk (Beras Premium) | AH12: Nasi Uduk (Beras)
S13: =IFERROR(__xludf.DUMMYFUNCTION("""COMPUTED_VALUE"""),"Tumis Sawi Putih Wortel") -> Tumis Sawi Putih Wortel | Y13: {=IF('STANDAR RESEP'!A13="", "", TRANSPOSE(INDIRECT(SUBSTITUTE(SUBSTITUTE(SUBSTITUTE('STANDAR RESEP'!A13, " ", "_"), "(", ""), ")", ""))))} -> Nasi Daun Jeruk (Beras Premium) | Z13: Nasi Daun Jeruk (Beras) | AA13: Nasi Kuning (Beras Premium) | AB13: Nasi Kuning (Beras) | AC13: Nasi Liwet (Beras Premium) | AD13: Nasi Liwet (Beras) | AE13: Nasi Putih (Beras Premium) | AF13: Nasi Putih (Beras) | AG13: Nasi Uduk (Beras Premium) | AH13: Nasi Uduk (Beras)
S14: =IFERROR(__xludf.DUMMYFUNCTION("""COMPUTED_VALUE"""),"Tumis Wortel Jagung Pipil") -> Tumis Wortel Jagung Pipil | Y14: {=IF('STANDAR RESEP'!A14="", "", TRANSPOSE(INDIRECT(SUBSTITUTE(SUBSTITUTE(SUBSTITUTE('STANDAR RESEP'!A14, " ", "_"), "(", ""), ")", ""))))} -> Nasi Daun Jeruk (Beras Premium) | Z14: Nasi Daun Jeruk (Beras) | AA14: Nasi Kuning (Beras Premium) | AB14: Nasi Kuning (Beras) | AC14: Nasi Liwet (Beras Premium) | AD14: Nasi Liwet (Beras) | AE14: Nasi Putih (Beras Premium) | AF14: Nasi Putih (Beras) | AG14: Nasi Uduk (Beras Premium) | AH14: Nasi Uduk (Beras)
Y15: {=IF('STANDAR RESEP'!A15="", "", TRANSPOSE(INDIRECT(SUBSTITUTE(SUBSTITUTE(SUBSTITUTE('STANDAR RESEP'!A15, " ", "_"), "(", ""), ")", ""))))} -> Nasi Daun Jeruk (Beras Premium) | Z15: Nasi Daun Jeruk (Beras) | AA15: Nasi Kuning (Beras Premium) | AB15: Nasi Kuning (Beras) | AC15: Nasi Liwet (Beras Premium) | AD15: Nasi Liwet (Beras) | AE15: Nasi Putih (Beras Premium) | AF15: Nasi Putih (Beras) | AG15: Nasi Uduk (Beras Premium) | AH15: Nasi Uduk (Beras)
Y16: {=IF('STANDAR RESEP'!A16="", "", TRANSPOSE(INDIRECT(SUBSTITUTE(SUBSTITUTE(SUBSTITUTE('STANDAR RESEP'!A16, " ", "_"), "(", ""), ")", ""))))} -> Nasi Daun Jeruk (Beras Premium) | Z16: Nasi Daun Jeruk (Beras) | AA16: Nasi Kuning (Beras Premium) | AB16: Nasi Kuning (Beras) | AC16: Nasi Liwet (Beras Premium) | AD16: Nasi Liwet (Beras) | AE16: Nasi Putih (Beras Premium) | AF16: Nasi Putih (Beras) | AG16: Nasi Uduk (Beras Premium) | AH16: Nasi Uduk (Beras)
Y17: {=IF('STANDAR RESEP'!A17="", "", TRANSPOSE(INDIRECT(SUBSTITUTE(SUBSTITUTE(SUBSTITUTE('STANDAR RESEP'!A17, " ", "_"), "(", ""), ")", ""))))} -> Nasi Daun Jeruk (Beras Premium) | Z17: Nasi Daun Jeruk (Beras) | AA17: Nasi Kuning (Beras Premium) | AB17: Nasi Kuning (Beras) | AC17: Nasi Liwet (Beras Premium) | AD17: Nasi Liwet (Beras) | AE17: Nasi Putih (Beras Premium) | AF17: Nasi Putih (Beras) | AG17: Nasi Uduk (Beras Premium) | AH17: Nasi Uduk (Beras)
Y18: {=IF('STANDAR RESEP'!A18="", "", TRANSPOSE(INDIRECT(SUBSTITUTE(SUBSTITUTE(SUBSTITUTE('STANDAR RESEP'!A18, " ", "_"), "(", ""), ")", ""))))} -> Nasi Daun Jeruk (Beras Premium) | Z18: Nasi Daun Jeruk (Beras) | AA18: Nasi Kuning (Beras Premium) | AB18: Nasi Kuning (Beras) | AC18: Nasi Liwet (Beras Premium) | AD18: Nasi Liwet (Beras) | AE18: Nasi Putih (Beras Premium) | AF18: Nasi Putih (Beras) | AG18: Nasi Uduk (Beras Premium) | AH18: Nasi Uduk (Beras)
Y19: {=IF('STANDAR RESEP'!A19="", "", TRANSPOSE(INDIRECT(SUBSTITUTE(SUBSTITUTE(SUBSTITUTE('STANDAR RESEP'!A19, " ", "_"), "(", ""), ")", ""))))} -> Nasi Daun Jeruk (Beras Premium) | Z19: Nasi Daun Jeruk (Beras) | AA19: Nasi Kuning (Beras Premium) | AB19: Nasi Kuning (Beras) | AC19: Nasi Liwet (Beras Premium) | AD19: Nasi Liwet (Beras) | AE19: Nasi Putih (Beras Premium) | AF19: Nasi Putih (Beras) | AG19: Nasi Uduk (Beras Premium) | AH19: Nasi Uduk (Beras)
Y20: {=IF('STANDAR RESEP'!A20="", "", TRANSPOSE(INDIRECT(SUBSTITUTE(SUBSTITUTE(SUBSTITUTE('STANDAR RESEP'!A20, " ", "_"), "(", ""), ")", ""))))} -> Nasi Daun Jeruk (Beras Premium) | Z20: Nasi Daun Jeruk (Beras) | AA20: Nasi Kuning (Beras Premium) | AB20: Nasi Kuning (Beras) | AC20: Nasi Liwet (Beras Premium) | AD20: Nasi Liwet (Beras) | AE20: Nasi Putih (Beras Premium) | AF20: Nasi Putih (Beras) | AG20: Nasi Uduk (Beras Premium) | AH20: Nasi Uduk (Beras)
Y21: {=IF('STANDAR RESEP'!A21="", "", TRANSPOSE(INDIRECT(SUBSTITUTE(SUBSTITUTE(SUBSTITUTE('STANDAR RESEP'!A21, " ", "_"), "(", ""), ")", ""))))} -> Nasi Daun Jeruk (Beras Premium) | Z21: Nasi Daun Jeruk (Beras) | AA21: Nasi Kuning (Beras Premium) | AB21: Nasi Kuning (Beras) | AC21: Nasi Liwet (Beras Premium) | AD21: Nasi Liwet (Beras) | AE21: Nasi Putih (Beras Premium) | AF21: Nasi Putih (Beras) | AG21: Nasi Uduk (Beras Premium) | AH21: Nasi Uduk (Beras)
Y22: {=IF('STANDAR RESEP'!A22="", "", TRANSPOSE(INDIRECT(SUBSTITUTE(SUBSTITUTE(SUBSTITUTE('STANDAR RESEP'!A22, " ", "_"), "(", ""), ")", ""))))} -> Nasi Daun Jeruk (Beras Premium) | Z22: Nasi Daun Jeruk (Beras) | AA22: Nasi Kuning (Beras Premium) | AB22: Nasi Kuning (Beras) | AC22: Nasi Liwet (Beras Premium) | AD22: Nasi Liwet (Beras) | AE22: Nasi Putih (Beras Premium) | AF22: Nasi Putih (Beras) | AG22: Nasi Uduk (Beras Premium) | AH22: Nasi Uduk (Beras)
Y23: {=IF('STANDAR RESEP'!A23="", "", TRANSPOSE(INDIRECT(SUBSTITUTE(SUBSTITUTE(SUBSTITUTE('STANDAR RESEP'!A23, " ", "_"), "(", ""), ")", ""))))} -> Nasi Daun Jeruk (Beras Premium) | Z23: Nasi Daun Jeruk (Beras) | AA23: Nasi Kuning (Beras Premium) | AB23: Nasi Kuning (Beras) | AC23: Nasi Liwet (Beras Premium) | AD23: Nasi Liwet (Beras) | AE23: Nasi Putih (Beras Premium) | AF23: Nasi Putih (Beras) | AG23: Nasi Uduk (Beras Premium) | AH23: Nasi Uduk (Beras)
Y24: {=IF('STANDAR RESEP'!A24="", "", TRANSPOSE(INDIRECT(SUBSTITUTE(SUBSTITUTE(SUBSTITUTE('STANDAR RESEP'!A24, " ", "_"), "(", ""), ")", ""))))} -> Nasi Daun Jeruk (Beras Premium) | Z24: Nasi Daun Jeruk (Beras) | AA24: Nasi Kuning (Beras Premium) | AB24: Nasi Kuning (Beras) | AC24: Nasi Liwet (Beras Premium) | AD24: Nasi Liwet (Beras) | AE24: Nasi Putih (Beras Premium) | AF24: Nasi Putih (Beras) | AG24: Nasi Uduk (Beras Premium) | AH24: Nasi Uduk (Beras)
Y25: {=IF('STANDAR RESEP'!A26="", "", TRANSPOSE(INDIRECT(SUBSTITUTE(SUBSTITUTE(SUBSTITUTE('STANDAR RESEP'!A26, " ", "_"), "(", ""), ")", ""))))} -> Nasi Daun Jeruk (Beras Premium) | Z25: Nasi Daun Jeruk (Beras) | AA25: Nasi Kuning (Beras Premium) | AB25: Nasi Kuning (Beras) | AC25: Nasi Liwet (Beras Premium) | AD25: Nasi Liwet (Beras) | AE25: Nasi Putih (Beras Premium) | AF25: Nasi Putih (Beras) | AG25: Nasi Uduk (Beras Premium) | AH25: Nasi Uduk (Beras)
Y26: {=IF('STANDAR RESEP'!A27="", "", TRANSPOSE(INDIRECT(SUBSTITUTE(SUBSTITUTE(SUBSTITUTE('STANDAR RESEP'!A27, " ", "_"), "(", ""), ")", ""))))} -> Nasi Daun Jeruk (Beras Premium) | Z26: Nasi Daun Jeruk (Beras) | AA26: Nasi Kuning (Beras Premium) | AB26: Nasi Kuning (Beras) | AC26: Nasi Liwet (Beras Premium) | AD26: Nasi Liwet (Beras) | AE26: Nasi Putih (Beras Premium) | AF26: Nasi Putih (Beras) | AG26: Nasi Uduk (Beras Premium) | AH26: Nasi Uduk (Beras)
Y27: {=IF('STANDAR RESEP'!A28="", "", TRANSPOSE(INDIRECT(SUBSTITUTE(SUBSTITUTE(SUBSTITUTE('STANDAR RESEP'!A28, " ", "_"), "(", ""), ")", ""))))} -> Nasi Daun Jeruk (Beras Premium) | Z27: Nasi Daun Jeruk (Beras) | AA27: Nasi Kuning (Beras Premium) | AB27: Nasi Kuning (Beras) | AC27: Nasi Liwet (Beras Premium) | AD27: Nasi Liwet (Beras) | AE27: Nasi Putih (Beras Premium) | AF27: Nasi Putih (Beras) | AG27: Nasi Uduk (Beras Premium) | AH27: Nasi Uduk (Beras)
Y28: {=IF('STANDAR RESEP'!A29="", "", TRANSPOSE(INDIRECT(SUBSTITUTE(SUBSTITUTE(SUBSTITUTE('STANDAR RESEP'!A29, " ", "_"), "(", ""), ")", ""))))} -> Nasi Daun Jeruk (Beras Premium) | Z28: Nasi Daun Jeruk (Beras) | AA28: Nasi Kuning (Beras Premium) | AB28: Nasi Kuning (Beras) | AC28: Nasi Liwet (Beras Premium) | AD28: Nasi Liwet (Beras) | AE28: Nasi Putih (Beras Premium) | AF28: Nasi Putih (Beras) | AG28: Nasi Uduk (Beras Premium) | AH28: Nasi Uduk (Beras)
Y29: {=IF('STANDAR RESEP'!A30="", "", TRANSPOSE(INDIRECT(SUBSTITUTE(SUBSTITUTE(SUBSTITUTE('STANDAR RESEP'!A30, " ", "_"), "(", ""), ")", ""))))} -> Nasi Daun Jeruk (Beras Premium) | Z29: Nasi Daun Jeruk (Beras) | AA29: Nasi Kuning (Beras Premium) | AB29: Nasi Kuning (Beras) | AC29: Nasi Liwet (Beras Premium) | AD29: Nasi Liwet (Beras) | AE29: Nasi Putih (Beras Premium) | AF29: Nasi Putih (Beras) | AG29: Nasi Uduk (Beras Premium) | AH29: Nasi Uduk (Beras)
Y30: {=IF('STANDAR RESEP'!A31="", "", TRANSPOSE(INDIRECT(SUBSTITUTE(SUBSTITUTE(SUBSTITUTE('STANDAR RESEP'!A31, " ", "_"), "(", ""), ")", ""))))} -> Nasi Daun Jeruk (Beras Premium) | Z30: Nasi Daun Jeruk (Beras) | AA30: Nasi Kuning (Beras Premium) | AB30: Nasi Kuning (Beras) | AC30: Nasi Liwet (Beras Premium) | AD30: Nasi Liwet (Beras) | AE30: Nasi Putih (Beras Premium) | AF30: Nasi Putih (Beras) | AG30: Nasi Uduk (Beras Premium) | AH30: Nasi Uduk (Beras)
Y31: {=IF('STANDAR RESEP'!A32="", "", TRANSPOSE(INDIRECT(SUBSTITUTE(SUBSTITUTE(SUBSTITUTE('STANDAR RESEP'!A32, " ", "_"), "(", ""), ")", ""))))} -> Nasi Daun Jeruk (Beras Premium) | Z31: Nasi Daun Jeruk (Beras) | AA31: Nasi Kuning (Beras Premium) | AB31: Nasi Kuning (Beras) | AC31: Nasi Liwet (Beras Premium) | AD31: Nasi Liwet (Beras) | AE31: Nasi Putih (Beras Premium) | AF31: Nasi Putih (Beras) | AG31: Nasi Uduk (Beras Premium) | AH31: Nasi Uduk (Beras)
Y32: {=IF('STANDAR RESEP'!A33="", "", TRANSPOSE(INDIRECT(SUBSTITUTE(SUBSTITUTE(SUBSTITUTE('STANDAR RESEP'!A33, " ", "_"), "(", ""), ")", ""))))} -> Nasi Daun Jeruk (Beras Premium) | Z32: Nasi Daun Jeruk (Beras) | AA32: Nasi Kuning (Beras Premium) | AB32: Nasi Kuning (Beras) | AC32: Nasi Liwet (Beras Premium) | AD32: Nasi Liwet (Beras) | AE32: Nasi Putih (Beras Premium) | AF32: Nasi Putih (Beras) | AG32: Nasi Uduk (Beras Premium) | AH32: Nasi Uduk (Beras)
Y33: {=IF('STANDAR RESEP'!A34="", "", TRANSPOSE(INDIRECT(SUBSTITUTE(SUBSTITUTE(SUBSTITUTE('STANDAR RESEP'!A34, " ", "_"), "(", ""), ")", ""))))} -> Nasi Daun Jeruk (Beras Premium) | Z33: Nasi Daun Jeruk (Beras) | AA33: Nasi Kuning (Beras Premium) | AB33: Nasi Kuning (Beras) | AC33: Nasi Liwet (Beras Premium) | AD33: Nasi Liwet (Beras) | AE33: Nasi Putih (Beras Premium) | AF33: Nasi Putih (Beras) | AG33: Nasi Uduk (Beras Premium) | AH33: Nasi Uduk (Beras)
Y34: {=IF('STANDAR RESEP'!A36="", "", TRANSPOSE(INDIRECT(SUBSTITUTE(SUBSTITUTE(SUBSTITUTE('STANDAR RESEP'!A36, " ", "_"), "(", ""), ")", ""))))} -> Nasi Daun Jeruk (Beras Premium) | Z34: Nasi Daun Jeruk (Beras) | AA34: Nasi Kuning (Beras Premium) | AB34: Nasi Kuning (Beras) | AC34: Nasi Liwet (Beras Premium) | AD34: Nasi Liwet (Beras) | AE34: Nasi Putih (Beras Premium) | AF34: Nasi Putih (Beras) | AG34: Nasi Uduk (Beras Premium) | AH34: Nasi Uduk (Beras)
Y35: {=IF('STANDAR RESEP'!A37="", "", TRANSPOSE(INDIRECT(SUBSTITUTE(SUBSTITUTE(SUBSTITUTE('STANDAR RESEP'!A37, " ", "_"), "(", ""), ")", ""))))} -> Nasi Daun Jeruk (Beras Premium) | Z35: Nasi Daun Jeruk (Beras) | AA35: Nasi Kuning (Beras Premium) | AB35: Nasi Kuning (Beras) | AC35: Nasi Liwet (Beras Premium) | AD35: Nasi Liwet (Beras) | AE35: Nasi Putih (Beras Premium) | AF35: Nasi Putih (Beras) | AG35: Nasi Uduk (Beras Premium) | AH35: Nasi Uduk (Beras)
Y36: {=IF('STANDAR RESEP'!A38="", "", TRANSPOSE(INDIRECT(SUBSTITUTE(SUBSTITUTE(SUBSTITUTE('STANDAR RESEP'!A38, " ", "_"), "(", ""), ")", ""))))} -> Nasi Daun Jeruk (Beras Premium) | Z36: Nasi Daun Jeruk (Beras) | AA36: Nasi Kuning (Beras Premium) | AB36: Nasi Kuning (Beras) | AC36: Nasi Liwet (Beras Premium) | AD36: Nasi Liwet (Beras) | AE36: Nasi Putih (Beras Premium) | AF36: Nasi Putih (Beras) | AG36: Nasi Uduk (Beras Premium) | AH36: Nasi Uduk (Beras)
Y37: {=IF('STANDAR RESEP'!A39="", "", TRANSPOSE(INDIRECT(SUBSTITUTE(SUBSTITUTE(SUBSTITUTE('STANDAR RESEP'!A39, " ", "_"), "(", ""), ")", ""))))} -> Nasi Daun Jeruk (Beras Premium) | Z37: Nasi Daun Jeruk (Beras) | AA37: Nasi Kuning (Beras Premium) | AB37: Nasi Kuning (Beras) | AC37: Nasi Liwet (Beras Premium) | AD37: Nasi Liwet (Beras) | AE37: Nasi Putih (Beras Premium) | AF37: Nasi Putih (Beras) | AG37: Nasi Uduk (Beras Premium) | AH37: Nasi Uduk (Beras)
Y38: {=IF('STANDAR RESEP'!A40="", "", TRANSPOSE(INDIRECT(SUBSTITUTE(SUBSTITUTE(SUBSTITUTE('STANDAR RESEP'!A40, " ", "_"), "(", ""), ")", ""))))} -> Nasi Daun Jeruk (Beras Premium) | Z38: Nasi Daun Jeruk (Beras) | AA38: Nasi Kuning (Beras Premium) | AB38: Nasi Kuning (Beras) | AC38: Nasi Liwet (Beras Premium) | AD38: Nasi Liwet (Beras) | AE38: Nasi Putih (Beras Premium) | AF38: Nasi Putih (Beras) | AG38: Nasi Uduk (Beras Premium) | AH38: Nasi Uduk (Beras)
Y39: {=IF('STANDAR RESEP'!A41="", "", TRANSPOSE(INDIRECT(SUBSTITUTE(SUBSTITUTE(SUBSTITUTE('STANDAR RESEP'!A41, " ", "_"), "(", ""), ")", ""))))} -> Nasi Daun Jeruk (Beras Premium) | Z39: Nasi Daun Jeruk (Beras) | AA39: Nasi Kuning (Beras Premium) | AB39: Nasi Kuning (Beras) | AC39: Nasi Liwet (Beras Premium) | AD39: Nasi Liwet (Beras) | AE39: Nasi Putih (Beras Premium) | AF39: Nasi Putih (Beras) | AG39: Nasi Uduk (Beras Premium) | AH39: Nasi Uduk (Beras)
Y40: {=IF('STANDAR RESEP'!A43="", "", TRANSPOSE(INDIRECT(SUBSTITUTE(SUBSTITUTE(SUBSTITUTE('STANDAR RESEP'!A43, " ", "_"), "(", ""), ")", ""))))} -> Nasi Daun Jeruk (Beras Premium) | Z40: Nasi Daun Jeruk (Beras) | AA40: Nasi Kuning (Beras Premium) | AB40: Nasi Kuning (Beras) | AC40: Nasi Liwet (Beras Premium) | AD40: Nasi Liwet (Beras) | AE40: Nasi Putih (Beras Premium) | AF40: Nasi Putih (Beras) | AG40: Nasi Uduk (Beras Premium) | AH40: Nasi Uduk (Beras)
...

Sheet Sheet7

Sheet Sheet3
A1: KODE BARANG | B1: NAMA BARANG | C1: UNIT | D1: UNIT BELI | E1: HARGA LAMA | F1: HARGA BARU | G1: UPDATE HARGA | H1: USE | I1: HARGA PER UNIT
